<?xml version="1.0" ?>
<!-- =================================================================================== -->
<!-- |    This document was autogenerated by xacro from j2n6s300_standalone.xacro      | -->
<!-- |    EDITING THIS FILE BY HAND IS NOT RECOMMENDED                                 | -->
<!-- =================================================================================== -->
<!-- j2n6s300 refers to jaco v2 6DOF non-spherical 3fingers -->


<robot name="allegrokinova" xmlns:body="http://playerstage.sourceforge.net/gazebo/xmlschema/#body" xmlns:controller="http://playerstage.sourceforge.net/gazebo/xmlschema/#controller" xmlns:gazebo="http://playerstage.sourceforge.net/gazebo/xmlschema/#gz" xmlns:geom="http://playerstage.sourceforge.net/gazebo/xmlschema/#geom" xmlns:interface="http://playerstage.sourceforge.net/gazebo/xmlschema/#interface" xmlns:joint="http://playerstage.sourceforge.net/gazebo/xmlschema/#joint" xmlns:model="http://playerstage.sourceforge.net/gazebo/xmlschema/#model" xmlns:physics="http://playerstage.sourceforge.net/gazebo/xmlschema/#physics" xmlns:renderable="http://playerstage.sourceforge.net/gazebo/xmlschema/#renderable" xmlns:rendering="http://playerstage.sourceforge.net/gazebo/xmlschema/#rendering" xmlns:sensor="http://playerstage.sourceforge.net/gazebo/xmlschema/#sensor" xmlns:xi="http://www.w3.org/2001/XInclude">
  <!-- links      		mesh_no
   base           		0
   shoulder       		1
   arm            		2
   forearm        		3
   wrist          		4
   arm_mico       		5
   arm_half1 (7dof)		6
   arm_half2 (7dof)		7
   wrist_spherical_1  8
   wrist_spherical_2  9

   hand 3 finger  		55
   hand_2finger   		56
   finger_proximal		57
   finger_distal      58
-->
  <!-- links      		mesh_no
   base           		0
   shoulder       		1
   arm            		2
   forearm        		3
   wrist          		4
   arm_mico       		5
   arm_half1 (7dof)		6
   arm_half2 (7dof)		7
   wrist_spherical_1  8
   wrist_spherical_2  9

   hand 3 finger  		55
   hand_2finger   		56
   finger_proximal		57
   finger_distal      58
   <color rgba="0.792156862745098 0.819607843137255 0.933333333333333 1"/>
-->
 <link name="kinova_link_base">
    <visual>
      <geometry>
        <mesh filename="package://kinova_description/meshes/base_smoothed.obj"/>
      </geometry>
      <material name="carbon_fiber">
       <color rgba="0.792156862745098 0.819607843137255 0.933333333333333 1"/>
      </material>
    </visual>
    <collision>
      <geometry>
        <mesh filename="package://kinova_description/meshes/base.STL"/>
      </geometry>
    </collision>
    <inertial>
      <mass value="0.0"/>
      <origin rpy="0 0 0" xyz="0 0 0.1255"/>
      <inertia ixx="0.000951270861568" ixy="0" ixz="0" iyy="0.000951270861568" iyz="0" izz="0.000374272"/>
    </inertial>
  </link>

  <link name="kinova_link_1">
    <visual>
      <geometry>
        <mesh filename="package://kinova_description/meshes/shoulder_smoothed.obj"/>
      </geometry>
      <material name="carbon_fiber">
        <color rgba="0.792156862745098 0.819607843137255 0.933333333333333 1"/>
      </material>
    </visual>
    <visual>
      <geometry>
        <mesh filename="package://kinova_description/meshes/ring_big_smoothed.obj"/>
      </geometry>
        <material name="white">
        <color rgba="0.792156862745098 0.819607843137255 0.933333333333333 1"/>
      </material>
    </visual>
    <collision>
      <geometry>
        <mesh filename="package://kinova_description/meshes/shoulder.STL"/>
      </geometry>
    </collision>                       
    <inertial>
      <mass value="0.7477"/>
      <origin xyz="0 -0.002 -0.0605"/>
      <inertia ixx="0.00152031725204" ixy="0" ixz="0" iyy="0.00152031725204" iyz="0" izz="0.00059816"/>
    </inertial>
  </link>
  <joint name="kinova_joint_1" type="revolute">
    <parent link="kinova_link_base"/>
    <child link="kinova_link_1"/>
    <axis xyz="0 0 1"/>
    <limit effort="30.5" lower="-6.28318530718" upper="6.28318530718" velocity="15"/>
    <origin rpy="0 3.14159265359 0" xyz="0 0 0.15675"/>
    <dynamics damping="0.0" friction="0.01"/>
  </joint>
  <link name="kinova_link_2">
    <visual>
      <geometry>
        <mesh filename="package://kinova_description/meshes/arm_smoothed.obj"/>
      </geometry>
      <material name="carbon_fiber">
        <color rgba="0.792156862745098 0.819607843137255 0.933333333333333 1"/>
      </material>
    </visual>
    <visual>
      <geometry>
        <mesh filename="package://kinova_description/meshes/ring_big_smoothed.obj"/>
      </geometry>
       <material name="white">
        <color rgba="0.792156862745098 0.819607843137255 0.933333333333333 1"/>
      </material>
    </visual>
    <collision>
      <geometry>
        <mesh filename="package://kinova_description/meshes/arm.STL"/>
      </geometry>
    </collision>                        
    <inertial>
      <mass value="0.99"/>
      <origin xyz="0 -0.2065 -0.01"/>
      <inertia ixx="0.010502207991" ixy="0" ixz="0" iyy="0.000792" iyz="0" izz="0.010502207991"/>
    </inertial>
  </link>
  <joint name="kinova_joint_2" type="revolute">
    <parent link="kinova_link_1"/>
    <child link="kinova_link_2"/>
    <axis xyz="0 0 1"/>
    <limit effort="30.5" lower="-6.28318530718" upper="6.28318530718" velocity="15"/>
    <origin rpy="-1.57079632679 0 3.14159265359" xyz="0 0.0016 -0.11875"/>
    <dynamics damping="0.0" friction="0.01"/>
  </joint>
  <link name="kinova_link_3">
    <visual>
      <geometry>
        <mesh filename="package://kinova_description/meshes/forearm_smoothed.obj"/>
      </geometry>
      <material name="carbon_fiber">
        <color rgba="0.792156862745098 0.819607843137255 0.933333333333333 1"/>
      </material>
    </visual>
    <visual>
      <geometry>
        <mesh filename="package://kinova_description/meshes/ring_big_smoothed.obj"/>
      </geometry>
       <material name="white">
        <color rgba="0.792156862745098 0.819607843137255 0.933333333333333 1"/>
      </material>
    </visual>
    <collision>
      <geometry>
        <mesh filename="package://kinova_description/meshes/forearm.STL"/>
      </geometry>
    </collision>     
    <inertial>
      <mass value="0.6763"/>
      <origin xyz="0 0.081 -0.0086"/>
      <inertia ixx="0.00142022431908" ixy="0" ixz="0" iyy="0.000304335" iyz="0" izz="0.00142022431908"/>
    </inertial>
  </link>
  <joint name="kinova_joint_3" type="revolute">
    <parent link="kinova_link_2"/>
    <child link="kinova_link_3"/>
    <axis xyz="0 0 1"/>
    <limit effort="30.5" lower="-6.28318530718" upper="6.28318530718" velocity="15"/>
    <origin rpy="0 3.14159265359 0" xyz="0 -0.410 0"/>
    <dynamics damping="0.0" friction="0.01"/>
  </joint>
  <link name="kinova_link_4">
    <visual>
      <geometry>
        <mesh filename="package://kinova_description/meshes/wrist_spherical_1_smoothed.obj"/>
      </geometry>
      <material name="carbon_fiber">
        <color rgba="0.792156862745098 0.819607843137255 0.933333333333333 1"/>
      </material>
    </visual>
    <visual>
      <geometry>
        <mesh filename="package://kinova_description/meshes/ring_small_smoothed.obj"/>
      </geometry>
       <material name="white">
        <color rgba="0.792156862745098 0.819607843137255 0.933333333333333 1"/>
       </material>
    </visual>
    <collision>
      <geometry>
        <mesh filename="package://kinova_description/meshes/wrist_spherical_1.STL"/>
      </geometry>
    </collision>          
    <inertial>
      <mass value="0.463"/>
      <origin xyz="0 0.0028848942 -0.0541932613"/>
      <inertia ixx="0.0004321316048" ixy="0" ixz="0" iyy="0.0004321316048" iyz="0" izz="9.26e-05"/>
    </inertial>
  </link>
  <joint name="kinova_joint_4" type="revolute">
    <parent link="kinova_link_3"/>
    <child link="kinova_link_4"/>
    <axis xyz="0 0 1"/>
    <limit effort="6.8" lower="-6.28318530718" upper="6.28318530718" velocity="15"/>
    <origin rpy="-1.57079632679 0 3.14159265359" xyz="0 0.2073 -0.0114"/>
    <dynamics damping="0.0" friction="0.01"/>
  </joint>
  <link name="kinova_link_5">
    <visual>
      <geometry>
        <mesh filename="package://kinova_description/meshes/wrist_spherical_2_smoothed.obj"/>
      </geometry>
      <material name="carbon_fiber">
        <color rgba="0.792156862745098 0.819607843137255 0.933333333333333 1"/>
      </material>
    </visual>
    <visual>
      <geometry>
        <mesh filename="package://kinova_description/meshes/ring_small_smoothed.obj"/>
      </geometry>
       <material name="white">
        <color rgba="0.792156862745098 0.819607843137255 0.933333333333333 1"/>
       </material>
    </visual>
    <collision>
      <geometry>
        <mesh filename="package://kinova_description/meshes/wrist_spherical_2.STL"/>
      </geometry>
    </collision>           
    <inertial>
      <mass value="0.463"/>
      <origin xyz="0 0.0497208855 -0.0028562765"/>
      <inertia ixx="0.0004321316048" ixy="0" ixz="0" iyy="9.26e-05" iyz="0" izz="0.0004321316048"/>
    </inertial>
  </link>
  <joint name="kinova_joint_5" type="revolute">
    <parent link="kinova_link_4"/>
    <child link="kinova_link_5"/>
    <axis xyz="0 0 1"/>
    <limit effort="6.8" lower="-6.28318530718" upper="6.28318530718" velocity="15"/>
    <origin rpy="1.57079632679 0 3.14159265359" xyz="0 0 -0.10375"/>
    <dynamics damping="0.0" friction="0.01"/>
  </joint>
  <link name="kinova_link_6">
    <visual>
      <geometry>
        <mesh filename="package://kinova_description/meshes/hand_3finger_smoothed.obj"/>
      </geometry>
      <material name="carbon_fiber">
       <color rgba="0.792156862745098 0.819607843137255 0.933333333333333 1"/>
      </material>
    </visual>
      <visual>
      <geometry>
        <mesh filename="package://kinova_description/meshes/ring_small_smoothed.obj"/>
      </geometry>
       <material name="white">
        <color rgba="0.792156862745098 0.819607843137255 0.933333333333333 1"/>
      </material>
    </visual>
    <collision>
      <geometry>
        <mesh filename="package://kinova_description/meshes/hand_3finger.STL"/>
      </geometry>
    </collision>              
    <inertial>
      <mass value="1.327"/>
      <origin xyz="0 0 -0.06"/>
      <inertia ixx="0.0003453236187" ixy="0" ixz="0" iyy="0.0003453236187" iyz="0" izz="0.0005816"/>
    </inertial>
  </link>
  <joint name="kinova_joint_6" type="revolute">
    <parent link="kinova_link_5"/>
    <child link="kinova_link_6"/>
    <axis xyz="0 0 1"/>
    <limit effort="6.8" lower="-6.28318530718" upper="6.28318530718" velocity="15"/>
    <origin rpy="-1.57079632679 0 3.14159265359" xyz="0 0.10375 0"/>
    <dynamics damping="0.0" friction="0.01"/>
  </joint>
  
  <link name="kinova_end_effector">
      <!-- Inertial properties and a fixed revolute joint have been added to this link to make it possible to use the gazebo_link_attacher plugin -->
      <!-- Minor collision properties are added to avoid bug/crash when running model in Gazebo -->
      <visual>
        <geometry>
          <box size="0 0 0"/>
        </geometry>
      </visual>
      <collision>
        <geometry>
          <box size="0.0000001 0.0000001 0.0000001"/>
        </geometry>
      </collision>
      <inertial>
        <origin rpy="0 0 0" xyz="0.0 0.0 0.0"/>
        <mass value="0.0000001"/>
        <inertia ixx="0.000001" ixy="0" ixz="0" iyy="0.000001" iyz="0" izz="0.000001"/>
      </inertial>
  </link>
  <joint name="kinova_joint_end_effector" type="fixed">
      <!--joint name="${joint_name}" type="fixed"-->
      <parent link="kinova_link_6"/>
      <child link="kinova_end_effector"/>
      <axis xyz="0 0 0"/>
      <limit effort="2000" lower="0" upper="0" velocity="1"/>
      <origin rpy="3.14159265359 0 0" xyz="0 0 -0.1"/>
  </joint>
 
  <!-- BASE -->
  <link name="allegro_mount">
    <inertial>
      <mass value="0.05"/>
      <origin rpy="0 0 0" xyz="0 0 0"/>
      <inertia ixx="1e-4" ixy="0" ixz="0" iyy="1e-4" iyz="0" izz="1e-4"/>
    </inertial>
    <visual>
      <!-- <origin xyz="-0.0425 -0.0425 0" rpy="0 0 0" /> -->
      <origin rpy="0 0 0" xyz="0 0 0"/>
      <geometry>
        <mesh filename="package://allegro_hand_description/meshes/mounts/allegro_mount.obj"/>
      </geometry>
      <material name="color_j7"/>
    </visual>
    <collision>
      <!-- <origin xyz="-0.0425 -0.0425 0" rpy="0 0 0" /> -->
      <origin rpy="0 0 0" xyz="0 0 0"/>
      <geometry>
        <mesh filename="package://allegro_hand_description/meshes/mounts/allegro_mount.obj"/>
      </geometry>
    </collision>
  </link>
  <!-- <joint name="allegro_mount_joint1" type="fixed">
    
    <origin rpy="0 0 0" xyz="-0.00 -0.0 0.0"/>
    <parent link="iiwa7_link_ee"/>
    <child link="allegro_mount"/>

  </joint> -->
  <joint name="allegro_mount_joint" type="fixed">
    <!-- <origin xyz="0.065 0 0.0275" rpy="0 1.57 0" /> -->
    <origin rpy="0 -1.5708 0.785398" xyz="0.008219 -0.02063 0.08086"/>
    <parent link="allegro_mount"/>
    <child link="palm_link"/>

  </joint>
  
  <!-- BASE -->
  <link name="palm_link">
    <inertial>
      <mass value="0.4154"/>
      <origin rpy="0 0 0" xyz="0 0 0"/>
      <inertia ixx="1e-4" ixy="0" ixz="0" iyy="1e-4" iyz="0" izz="1e-4"/>
    </inertial>
    <visual>
      <geometry>
        <mesh filename="package://allegro_hand_description/meshes/allegro/base_link.obj"/>
      </geometry>
      <origin rpy="0 0 0" xyz="0 0 0 "/>
      <material name="Grey">
        <color rgba="0.2 0.2 0.2 1"/>
      </material>
    </visual>
    <collision>
      <origin rpy="0.0 0 0" xyz="0 0 0"/>
      <geometry>
        <mesh filename="package://allegro_hand_description/meshes/allegro/base_link.obj"/>
      </geometry>
    </collision>
  </link>
  <gazebo reference="palm_link">
    <material value="Gazebo/Grey"/>
  </gazebo>
  <!-- ============================================================================= -->
  <!-- FINGERS -->
  <!-- RIGHT HAND due to which finger is number 0 -->
  <!-- for LEFT HAND switch the sign of the **offset_origin_y** and **finger_angle_r** parameters-->
  <!-- [LINK 0, 4, 8] -->
  <link name="index_link_0">
    <collision>
      <geometry>
        <mesh filename="package://allegro_hand_description/meshes/link_0.0.STL"/>
      </geometry>
    </collision>
    <inertial>
      <mass value="0.005"/>
      <origin xyz="0 0 0"/>
      <inertia ixx="5.1458e-05" iyy="5.1458e-05" izz="6.125e-05" ixy="0" ixz="0" iyz="0"/>	
    </inertial>
    <visual>
      <geometry>
        <mesh filename="package://allegro_hand_description/meshes/link_0.0.STL"/>
      </geometry>
      <material name="Grey">
        <color rgba="0.2 0.2 0.2 1"/>
      </material>
    </visual>
  </link>
  <link name="index_link_1">
    <collision>
      <geometry>
        <mesh filename="package://allegro_hand_description/meshes/link_1.0.STL"/>
      </geometry>
    </collision>
    <inertial>
      <mass value="0.125164"/>
      <origin xyz="0.027 0 0"/>
      <inertia ixx="6.39979e-06" iyy="8.88687e-05" izz="9.13751e-05" ixy="-3.26531e-06" ixz="1.23963e-05" iyz="2.07384e-05"/>	
    </inertial>
    <visual>
      <geometry>
        <mesh filename="package://allegro_hand_description/meshes/link_1.0.STL"/>
      </geometry>
      <material name="Grey">
        <color rgba="0.2 0.2 0.2 1"/>
      </material>
    </visual>
  </link>
  <link name="index_link_2">
    <collision>
      <geometry>
        <mesh filename="package://allegro_hand_description/meshes/link_2.0.STL"/>
      </geometry>
    </collision>
    <inertial>
      <mass value="0.131691"/>
      <origin xyz="0.039 0 0"/>
      <inertia ixx="7.04217e-05" iyy="3.95744e-05" izz="6.61125e-05" ixy="-9.64342e-05" ixz="5.8796e-05" iyz="-3.62996e-05"/>	
    </inertial>
    <visual>
      <geometry>
        <mesh filename="package://allegro_hand_description/meshes/link_2.0.STL"/>
      </geometry>
      <material name="Grey">
        <color rgba="0.2 0.2 0.2 1"/>
      </material>
    </visual>
  </link>
  <link name="index_link_3">
    <collision>
      <geometry>
        <mesh filename="package://allegro_hand_description/meshes/link_3.0.STL"/>
      </geometry>
    </collision>
    <inertial>
      <mass value="0.0211922"/>
      <origin xyz="0.029 0 0"/>
      <inertia ixx="2.93743e-05" iyy="7.21391e-05" izz="7.59731e-05" ixy="-3.51896e-05" ixz="-6.31225e-05" iyz="-9.25392e-07"/>
    </inertial>
    <visual>
      <geometry>
        <mesh filename="package://allegro_hand_description/meshes/link_3.0.STL"/>
      </geometry>
      <material name="Green">
        <color rgba="0. 0.5 0. 1"/>
      </material>
    </visual>
  </link>
  <link name="middle_link_0">
    <collision>
      <geometry>
        <mesh filename="package://allegro_hand_description/meshes/allegro/primary_base.obj"/>
      </geometry>
    </collision>
    <inertial>
      <mass value="0.005"/>
      <origin xyz="0 0 0"/>
      <inertia ixx="5.1458e-05" iyy="5.1458e-05" izz="6.125e-05" ixy="0" ixz="0" iyz="0"/>	
    </inertial>
    <visual>
      <geometry>
        <mesh filename="package://allegro_hand_description/meshes/allegro/primary_base.obj"/>
      </geometry>
      <material name="Grey">
        <color rgba="0.2 0.2 0.2 1"/>
      </material>
    </visual>
  </link>
  <link name="middle_link_1">
    <collision>
      <geometry>
        <mesh filename="package://allegro_hand_description/meshes/allegro/primary_proximal.obj"/>
      </geometry>
    </collision>
    <inertial>
      <mass value="0.125164"/>
      <origin xyz="0.027 0 0"/>
      <inertia ixx="6.39979e-06" iyy="8.88687e-05" izz="9.13751e-05" ixy="-3.26531e-06" ixz="1.23963e-05" iyz="2.07384e-05"/>	
    </inertial>
    <visual>
      <geometry>
        <mesh filename="package://allegro_hand_description/meshes/allegro/primary_proximal.obj"/>
      </geometry>
      <material name="Grey">
        <color rgba="0.2 0.2 0.2 1"/>
      </material>
    </visual>
  </link>
  <link name="middle_link_2">
    <collision>
      <geometry>
        <mesh filename="package://allegro_hand_description/meshes/allegro/primary_medial.obj"/>
      </geometry>
    </collision>
    <inertial>
      <mass value="0.131691"/>
      <origin xyz="0.039 0 0"/>
      <inertia ixx="7.04217e-05" iyy="3.95744e-05" izz="6.61125e-05" ixy="-9.64342e-05" ixz="5.8796e-05" iyz="-3.62996e-05"/>	
    </inertial>
    <visual>
      <geometry>
        <mesh filename="package://allegro_hand_description/meshes/allegro/primary_medial.obj"/>
      </geometry>
      <material name="Grey">
        <color rgba="0.2 0.2 0.2 1"/>
      </material>
    </visual>
  </link>
  <link name="middle_link_3">
    <collision>
      <geometry>
        <mesh filename="package://allegro_hand_description/meshes/biotac/biotac_sensor.obj"/>
      </geometry>
    </collision>
    <inertial>
      <mass value="0.0211922"/>
      <origin xyz="0.029 0 0"/>
      <inertia ixx="2.93743e-05" iyy="7.21391e-05" izz="7.59731e-05" ixy="-3.51896e-05" ixz="-6.31225e-05" iyz="-9.25392e-07"/>
    </inertial>
    <visual>
      <geometry>
        <mesh filename="package://allegro_hand_description/meshes/biotac/biotac_sensor.obj"/>
      </geometry>
      <material name="Green">
        <color rgba="0 0.5 0 1"/>
      </material>
    </visual>
  </link>
  <link name="ring_link_0">
    <collision>
      <geometry>
        <mesh filename="package://allegro_hand_description/meshes/allegro/primary_base.obj"/>
      </geometry>
    </collision>
    <inertial>
      <mass value="0.005"/>
      <origin xyz="0 0 0"/>
      <inertia ixx="5.1458e-05" iyy="5.1458e-05" izz="6.125e-05" ixy="0" ixz="0" iyz="0"/>	
    </inertial>
    <visual>
      <geometry>
        <mesh filename="package://allegro_hand_description/meshes/allegro/primary_base.obj"/>
      </geometry>
      <material name="Grey">
        <color rgba="0.2 0.2 0.2 1"/>
      </material>
    </visual>
  </link>
  <link name="ring_link_1">
    <collision>
      <geometry>
        <mesh filename="package://allegro_hand_description/meshes/allegro/primary_proximal.obj"/>
      </geometry>
    </collision>
    <inertial>
      <mass value="0.125164"/>
      <origin xyz="0.027 0 0"/>
      <inertia ixx="6.39979e-06" iyy="8.88687e-05" izz="9.13751e-05" ixy="-3.26531e-06" ixz="1.23963e-05" iyz="2.07384e-05"/>	
    </inertial>
    <visual>
      <geometry>
        <mesh filename="package://allegro_hand_description/meshes/allegro/primary_proximal.obj"/>
      </geometry>
      <material name="Grey">
        <color rgba="0.2 0.2 0.2 1"/>
      </material>
    </visual>
  </link>
  <link name="ring_link_2">
    <collision>
      <geometry>
        <mesh filename="package://allegro_hand_description/meshes/allegro/primary_medial.obj"/>
      </geometry>
    </collision>
    <inertial>
      <mass value="0.131691"/>
      <origin xyz="0.039 0 0"/>
      <inertia ixx="7.04217e-05" iyy="3.95744e-05" izz="6.61125e-05" ixy="-9.64342e-05" ixz="5.8796e-05" iyz="-3.62996e-05"/>	
    </inertial>
    <visual>
      <geometry>
        <mesh filename="package://allegro_hand_description/meshes/allegro/primary_medial.obj"/>
      </geometry>
      <material name="Grey">
        <color rgba="0.2 0.2 0.2 1"/>
      </material>
    </visual>
  </link>
  <link name="ring_link_3">
    <collision>
      <geometry>
        <mesh filename="package://allegro_hand_description/meshes/biotac/biotac_sensor.obj"/>
      </geometry>
    </collision>
    <inertial>
      <mass value="0.0211922"/>
      <origin xyz="0.029 0 0"/>
      <inertia ixx="2.93743e-05" iyy="7.21391e-05" izz="7.59731e-05" ixy="-3.51896e-05" ixz="-6.31225e-05" iyz="-9.25392e-07"/>
    </inertial>
    <visual>
      <geometry>
        <mesh filename="package://allegro_hand_description/meshes/biotac/biotac_sensor.obj"/>
      </geometry>
      <material name="Green">
        <color rgba="0 0.5 0 1"/>
      </material>
    </visual>
  </link>
  <link name="thumb_link_0">
    <collision>
      <geometry>
        <mesh filename="package://allegro_hand_description/meshes/allegro/thumb_base.obj"/>
      </geometry>
    </collision>
    <inertial>
      <mass value="0.1"/>
      <inertia ixx="5.1458e-5" ixy="0" ixz="0" iyy="5.1458e-5" iyz="0" izz="6.125e-5"/>
    </inertial>
    <visual>
      <geometry>
        <mesh filename="package://allegro_hand_description/meshes/allegro/thumb_base.obj"/>
      </geometry>
      <material name="Grey">
        <color rgba="0.2 0.2 0.2 1"/>
      </material>
    </visual>
  </link>
  <link name="thumb_link_1">
    <collision>
      <geometry>
        <mesh filename="package://allegro_hand_description/meshes/allegro/thumb_proximal.obj"/>
      </geometry>
    </collision>
    <inertial>
      <mass value="0.1"/>
      <inertia ixx="5.1458e-5" ixy="0" ixz="0" iyy="5.1458e-5" iyz="0" izz="6.125e-5"/>
    </inertial>
    <visual>
      <geometry>
        <mesh filename="package://allegro_hand_description/meshes/allegro/thumb_proximal.obj"/>
      </geometry>
      <material name="Grey">
        <color rgba="0.2 0.2 0.2 1"/>
      </material>
    </visual>
  </link>
  <link name="thumb_link_2">
    <collision>
      <geometry>
        <mesh filename="package://allegro_hand_description/meshes/allegro/thumb_medial.obj"/>
      </geometry>
    </collision>
    <inertial>
      <mass value="0.1"/>
      <inertia ixx="5.1458e-5" ixy="0" ixz="0" iyy="5.1458e-5" iyz="0" izz="6.125e-5"/>
    </inertial>
    <visual>
      <geometry>
        <mesh filename="package://allegro_hand_description/meshes/allegro/thumb_medial.obj"/>
      </geometry>
      <material name="Grey">
        <color rgba="0.2 0.2 0.2 1"/>
      </material>
    </visual>
  </link>
  <link name="thumb_link_3">
    <collision>
      <geometry>
        <mesh filename="package://allegro_hand_description/meshes/biotac/biotac_sensor_thumb.obj"/>
      </geometry>
    </collision>
    <inertial>
      <mass value="0.1"/>
      <inertia ixx="5.1458e-5" ixy="0" ixz="0" iyy="5.1458e-5" iyz="0" izz="6.125e-5"/>
    </inertial>
    <visual>
      <geometry>
        <mesh filename="package://allegro_hand_description/meshes/biotac/biotac_sensor_thumb.obj"/>
      </geometry>
      <material name="Green">
        <color rgba="0 0.5 0 1"/>
      </material>
    </visual>
  </link>
  <joint name="index_joint_0" type="revolute">
    <axis xyz="0 0 1"/>
    <limit effort="0.35" lower="-0.558488888889" upper="0.558488888889" velocity="6.283"/>
    <origin rpy="3.1415 -1.57075 -0.0872638888889" xyz="0.0514302 -0.03632 -0.0113"/>
    <parent link="palm_link"/>
    <child link="index_link_0"/>
    <dynamics damping="0.0414019" friction="0.0523963"/>
  </joint>
  <joint name="index_joint_1" type="revolute">
    <axis xyz="0 0 1"/>
    <limit effort="0.35" lower="-0.279244444444" upper="1.727825" velocity="6.283"/>
    <origin rpy="3.1415 -1.57075 1.57075" xyz="0.0 0.0 0.0"/>
    <parent link="index_link_0"/>
    <child link="index_link_1"/>
    <dynamics damping="0.00587541" friction="0.0150275"/>
  </joint>
  <joint name="index_joint_2" type="revolute">
    <axis xyz="0 0 1"/>
    <limit effort="0.35" lower="-0.279244444444" upper="1.727825" velocity="6.283"/>
    <origin rpy="0.0 0.0 0.0" xyz="0.054 0.0 0.0"/>
    <parent link="index_link_1"/>
    <child link="index_link_2"/>
    <dynamics damping="0.010638" friction="0.00616359"/>
  </joint>
  <joint name="index_joint_3" type="revolute">
    <axis xyz="0 0 1"/>
    <limit effort="0.35" lower="-0.279244444444" upper="1.727825" velocity="6.283"/>
    <origin rpy="0.0 0.0 0.0" xyz="0.0384 0.0 0.0"/>
    <parent link="index_link_2"/>
    <child link="index_link_3"/>
    <dynamics damping="0.0226948" friction="0.0227036"/>
  </joint>
  <joint name="middle_joint_0" type="revolute">
    <axis xyz="0 0 1"/>
    <limit effort="0.35" lower="-0.558488888889" upper="0.558488888889" velocity="6.283"/>
    <origin rpy="3.1415 -1.57075 0" xyz="0.0537375 0.0087771 -0.0113"/>
    <parent link="palm_link"/>
    <child link="middle_link_0"/>
    <dynamics damping="0.0414019" friction="0.0523963"/>
  </joint>
  <joint name="middle_joint_1" type="revolute">
    <axis xyz="0 0 1"/>
    <limit effort="0.35" lower="-0.279244444444" upper="1.727825" velocity="6.283"/>
    <origin rpy="3.1415 -1.57075 1.57075" xyz="0.0 0.0 0.0"/>
    <parent link="middle_link_0"/>
    <child link="middle_link_1"/>
    <dynamics damping="0.00587541" friction="0.0150275"/>
  </joint>
  <joint name="middle_joint_2" type="revolute">
    <axis xyz="0 0 1"/>
    <limit effort="0.35" lower="-0.279244444444" upper="1.727825" velocity="6.283"/>
    <origin rpy="0.0 0.0 0.0" xyz="0.054 0.0 0.0"/>
    <parent link="middle_link_1"/>
    <child link="middle_link_2"/>
    <dynamics damping="0.010638" friction="0.00616359"/>
  </joint>
  <joint name="middle_joint_3" type="revolute">
    <axis xyz="0 0 1"/>
    <limit effort="0.35" lower="-0.279244444444" upper="1.727825" velocity="6.283"/>
    <origin rpy="0.0 0.0 0.0" xyz="0.0384 0.0 0.0"/>
    <parent link="middle_link_2"/>
    <child link="middle_link_3"/>
    <dynamics damping="0.0226948" friction="0.0227036"/>
  </joint>
  <joint name="ring_joint_0" type="revolute">
    <axis xyz="0 0 1"/>
    <limit effort="0.35" lower="-0.558488888889" upper="0.558488888889" velocity="6.283"/>
    <origin rpy="3.1415 -1.57075 0.0872638888889" xyz="0.0514302 0.0538749 -0.0113"/>
    <parent link="palm_link"/>
    <child link="ring_link_0"/>
    <dynamics damping="0.0414019" friction="0.0523963"/>
  </joint>
  <joint name="ring_joint_1" type="revolute">
    <axis xyz="0 0 1"/>
    <limit effort="0.35" lower="-0.279244444444" upper="1.727825" velocity="6.283"/>
    <origin rpy="3.1415 -1.57075 1.57075" xyz="0.0 0.0 0.0"/>
    <parent link="ring_link_0"/>
    <child link="ring_link_1"/>
    <dynamics damping="0.00587541" friction="0.0150275"/>
  </joint>
  <joint name="ring_joint_2" type="revolute">
    <axis xyz="0 0 1"/>
    <limit effort="0.35" lower="-0.279244444444" upper="1.727825" velocity="6.283"/>
    <origin rpy="0.0 0.0 0.0" xyz="0.054 0.0 0.0"/>
    <parent link="ring_link_1"/>
    <child link="ring_link_2"/>
    <dynamics damping="0.010638" friction="0.00616359"/>
  </joint>
  <joint name="ring_joint_3" type="revolute">
    <axis xyz="0 0 1"/>
    <limit effort="0.35" lower="-0.279244444444" upper="1.727825" velocity="6.283"/>
    <origin rpy="0.0 0.0 0.0" xyz="0.0384 0.0 0.0"/>
    <parent link="ring_link_2"/>
    <child link="ring_link_3"/>
    <dynamics damping="0.0226948" friction="0.0227036"/>
  </joint>
  <joint name="thumb_joint_0" type="revolute">
    <axis xyz="0 0 1"/>
    <limit effort="0.35" lower="0.279244444444" upper="1.57075" velocity="6.283"/>
    <origin rpy="-1.57075 -1.57075 1.48348611111" xyz="-0.0367482 -0.0081281 -0.0295"/>
    <parent link="palm_link"/>
    <child link="thumb_link_0"/>
    <dynamics friction="0.035"/>
  </joint>
  <joint name="thumb_joint_1" type="revolute">
    <axis xyz="0 0 1"/>
    <limit effort="0.35" lower="-0.331602777778" upper="1.15188333333" velocity="6.283"/>
    <origin rpy="1.57075 0 0" xyz="0.005 0.0 0.0"/>
    <parent link="thumb_link_0"/>
    <child link="thumb_link_1"/>
    <dynamics friction="0.035"/>
  </joint>
  <joint name="thumb_joint_2" type="revolute">
    <axis xyz="0 0 1"/>
    <limit effort="0.35" lower="-0.279244444444" upper="1.727825" velocity="6.283"/>
    <origin rpy="3.1415 -1.57075 0.0" xyz="0 0 0.0554"/>
    <parent link="thumb_link_1"/>
    <child link="thumb_link_2"/>
    <dynamics friction="0.035"/>
  </joint>
  <joint name="thumb_joint_3" type="revolute">
    <axis xyz="0 0 1"/>
    <limit effort="0.35" lower="-0.279244444444" upper="1.76273055556" velocity="6.283"/>
    <origin rpy="0.0 0.0 0.0" xyz="0.0514 0.0 0.0"/>
    <parent link="thumb_link_2"/>
    <child link="thumb_link_3"/>
    <dynamics friction="0.035"/>
  </joint>
  <!-- ============================================================================= -->

  <!-- Create a different *root* for the allegro hand -->
  <!-- Note: this offset is just eyeballed... -->
  <joint name="kinova_allegro_hand" type="fixed">
    <parent link="kinova_end_effector"/>
    <child link="allegro_mount"/>
    <origin rpy="0 0 0" xyz="0 0 0"/>
  </joint>
  

</robot>
