<?xml version="1.0" ?>
<!-- =================================================================================== -->
<!-- |    This document was autogenerated by xacro from j2n6s300_standalone.xacro      | -->
<!-- |    EDITING THIS FILE BY HAND IS NOT RECOMMENDED                                 | -->
<!-- =================================================================================== -->
<!-- j2n6s300 refers to jaco v2 6DOF non-spherical 3fingers -->
<robot name="allegrokinova" xmlns:body="http://playerstage.sourceforge.net/gazebo/xmlschema/#body" xmlns:controller="http://playerstage.sourceforge.net/gazebo/xmlschema/#controller" xmlns:gazebo="http://playerstage.sourceforge.net/gazebo/xmlschema/#gz" xmlns:geom="http://playerstage.sourceforge.net/gazebo/xmlschema/#geom" xmlns:interface="http://playerstage.sourceforge.net/gazebo/xmlschema/#interface" xmlns:joint="http://playerstage.sourceforge.net/gazebo/xmlschema/#joint" xmlns:model="http://playerstage.sourceforge.net/gazebo/xmlschema/#model" xmlns:physics="http://playerstage.sourceforge.net/gazebo/xmlschema/#physics" xmlns:renderable="http://playerstage.sourceforge.net/gazebo/xmlschema/#renderable" xmlns:rendering="http://playerstage.sourceforge.net/gazebo/xmlschema/#rendering" xmlns:sensor="http://playerstage.sourceforge.net/gazebo/xmlschema/#sensor" xmlns:xi="http://www.w3.org/2001/XInclude">
  <!-- links      		mesh_no
   base           		0
   shoulder       		1
   arm            		2
   forearm        		3
   wrist          		4
   arm_mico       		5
   arm_half1 (7dof)		6
   arm_half2 (7dof)		7
   wrist_spherical_1  8
   wrist_spherical_2  9

   hand 3 finger  		55
   hand_2finger   		56
   finger_proximal		57
   finger_distal      58
-->
  <!-- links      		mesh_no
   base           		0
   shoulder       		1
   arm            		2
   forearm        		3
   wrist          		4
   arm_mico       		5
   arm_half1 (7dof)		6
   arm_half2 (7dof)		7
   wrist_spherical_1  8
   wrist_spherical_2  9

   hand 3 finger  		55
   hand_2finger   		56
   finger_proximal		57
   finger_distal      58
-->
  <link name="root"/>
  <!-- for gazebo -->
  <link name="world"/>
  <joint name="connect_root_and_world" type="fixed">
    <child link="root"/>
    <parent link="world"/>
    <origin rpy="0 0 0" xyz="0 0 0"/>
  </joint>
  <!-- ros_control plugin -->
  <gazebo>
    <plugin filename="libgazebo_ros_control.so" name="gazebo_ros_control">
      <robotNamespace>j2n6s300</robotNamespace>
      <robotSimType>gazebo_ros_control/DefaultRobotHWSim</robotSimType>
      <legacyModeNS>true</legacyModeNS>
    </plugin>
  </gazebo>
  <link name="j2n6s300_link_base">
    <visual>
      <geometry>
        <mesh filename="package://kinova_description/meshes/base.dae"/>
      </geometry>
      <material name="carbon_fiber">
        <color rgba="0.792156862745098 0.819607843137255 0.933333333333333 1"/>
      </material>
    </visual>
    <collision>
      <geometry>
        <mesh filename="package://kinova_description/meshes/base.dae"/>
      </geometry>
    </collision>
    <inertial>
      <mass value="0.46784"/>
      <origin rpy="0 0 0" xyz="0 0 0.1255"/>
      <inertia ixx="0.000951270861568" ixy="0" ixz="0" iyy="0.000951270861568" iyz="0" izz="0.00037427200000000004"/>
    </inertial>
  </link>
  <joint name="j2n6s300_joint_base" type="fixed">
    <parent link="root"/>
    <child link="j2n6s300_link_base"/>
    <axis xyz="0 0 0"/>
    <limit effort="0" lower="0" upper="0" velocity="0"/>
    <origin rpy="0 0 0" xyz="0 0 0"/>
    <dynamics damping="0.0" friction="0.0"/>
  </joint>
  <link name="j2n6s300_link_1">
    <visual>
      <geometry>
        <mesh filename="package://kinova_description/meshes/shoulder.dae"/>
      </geometry>
      <material name="carbon_fiber">
        <color rgba="0.792156862745098 0.819607843137255 0.933333333333333 1"/>
      </material>
    </visual>
    <visual>
      <geometry>
        <mesh filename="package://kinova_description/meshes/ring_big.dae"/>
      </geometry>
    </visual>
    <collision>
      <geometry>
        <mesh filename="package://kinova_description/meshes/shoulder.dae"/>
      </geometry>
    </collision>
    <inertial>
      <mass value="0.7477"/>
      <origin xyz="0 -0.002 -0.0605"/>
      <inertia ixx="0.0015203172520400004" ixy="0" ixz="0" iyy="0.0015203172520400004" iyz="0" izz="0.00059816"/>
    </inertial>
  </link>
  <joint name="j2n6s300_joint_1" type="continuous">
    <parent link="j2n6s300_link_base"/>
    <child link="j2n6s300_link_1"/>
    <axis xyz="0 0 1"/>
    <limit effort="40" lower="-6.283185307179586" upper="6.283185307179586" velocity="0.6283185307179586"/>
    <origin rpy="0 3.141592653589793 0" xyz="0 0 0.15675"/>
    <dynamics damping="0.0" friction="0.0"/>
  </joint>
  <transmission name="j2n6s300_joint_1_trans">
    <type>transmission_interface/SimpleTransmission</type>
    <joint name="j2n6s300_joint_1">
      <hardwareInterface>hardware_interface/EffortJointInterface</hardwareInterface>
    </joint>
    <actuator name="j2n6s300_joint_1_actuator">
      <hardwareInterface>hardware_interface/EffortJointInterface</hardwareInterface>
      <mechanicalReduction>160</mechanicalReduction>
    </actuator>
  </transmission>
  <!--For torque sensing in simulation-->
  <gazebo reference="j2n6s300_joint_1">
    <provideFeedback>true</provideFeedback>
  </gazebo>
  <gazebo>
    <plugin filename="libgazebo_ros_ft_sensor.so" name="ft_sensor">
      <updateRate>30.0</updateRate>
      <topicName>j2n6s300_joint_1_ft_sensor_topic</topicName>
      <jointName>j2n6s300_joint_1</jointName>
    </plugin>
  </gazebo>
  <link name="j2n6s300_link_2">
    <visual>
      <geometry>
        <mesh filename="package://kinova_description/meshes/arm.dae"/>
      </geometry>
      <material name="carbon_fiber">
        <color rgba="0.792156862745098 0.819607843137255 0.933333333333333 1"/>
      </material>
    </visual>
    <visual>
      <geometry>
        <mesh filename="package://kinova_description/meshes/ring_big.dae"/>
      </geometry>
    </visual>
    <collision>
      <geometry>
        <mesh filename="package://kinova_description/meshes/arm.dae"/>
      </geometry>
    </collision>
    <inertial>
      <mass value="0.99"/>
      <origin xyz="0 -0.2065 -0.01"/>
      <inertia ixx="0.010502207990999999" ixy="0" ixz="0" iyy="0.0007920000000000001" iyz="0" izz="0.010502207990999999"/>
    </inertial>
  </link>
  <joint name="j2n6s300_joint_2" type="revolute">
    <parent link="j2n6s300_link_1"/>
    <child link="j2n6s300_link_2"/>
    <axis xyz="0 0 1"/>
    <limit effort="80" lower="0.8203047484373349" upper="5.462880558742252" velocity="0.6283185307179586"/>
    <origin rpy="-1.5707963267948966 0 3.141592653589793" xyz="0 0.0016 -0.11875"/>
    <dynamics damping="0.0" friction="0.0"/>
  </joint>
  <transmission name="j2n6s300_joint_2_trans">
    <type>transmission_interface/SimpleTransmission</type>
    <joint name="j2n6s300_joint_2">
      <hardwareInterface>hardware_interface/EffortJointInterface</hardwareInterface>
    </joint>
    <actuator name="j2n6s300_joint_2_actuator">
      <hardwareInterface>hardware_interface/EffortJointInterface</hardwareInterface>
      <mechanicalReduction>160</mechanicalReduction>
    </actuator>
  </transmission>
  <!--For torque sensing in simulation-->
  <gazebo reference="j2n6s300_joint_2">
    <provideFeedback>true</provideFeedback>
  </gazebo>
  <gazebo>
    <plugin filename="libgazebo_ros_ft_sensor.so" name="ft_sensor">
      <updateRate>30.0</updateRate>
      <topicName>j2n6s300_joint_2_ft_sensor_topic</topicName>
      <jointName>j2n6s300_joint_2</jointName>
    </plugin>
  </gazebo>
  <link name="j2n6s300_link_3">
    <visual>
      <geometry>
        <mesh filename="package://kinova_description/meshes/forearm.dae"/>
      </geometry>
      <material name="carbon_fiber">
        <color rgba="0.792156862745098 0.819607843137255 0.933333333333333 1"/>
      </material>
    </visual>
    <visual>
      <geometry>
        <mesh filename="package://kinova_description/meshes/ring_big.dae"/>
      </geometry>
    </visual>
    <collision>
      <geometry>
        <mesh filename="package://kinova_description/meshes/forearm.dae"/>
      </geometry>
    </collision>
    <inertial>
      <mass value="0.6763"/>
      <origin xyz="0 0.081 -0.0086"/>
      <inertia ixx="0.0014202243190800001" ixy="0" ixz="0" iyy="0.000304335" iyz="0" izz="0.0014202243190800001"/>
    </inertial>
  </link>
  <joint name="j2n6s300_joint_3" type="revolute">
    <parent link="j2n6s300_link_2"/>
    <child link="j2n6s300_link_3"/>
    <axis xyz="0 0 1"/>
    <limit effort="40" lower="0.33161255787892263" upper="5.951572749300664" velocity="0.6283185307179586"/>
    <origin rpy="0 3.141592653589793 0" xyz="0 -0.410 0"/>
    <dynamics damping="0.0" friction="0.0"/>
  </joint>
  <transmission name="j2n6s300_joint_3_trans">
    <type>transmission_interface/SimpleTransmission</type>
    <joint name="j2n6s300_joint_3">
      <hardwareInterface>hardware_interface/EffortJointInterface</hardwareInterface>
    </joint>
    <actuator name="j2n6s300_joint_3_actuator">
      <hardwareInterface>hardware_interface/EffortJointInterface</hardwareInterface>
      <mechanicalReduction>160</mechanicalReduction>
    </actuator>
  </transmission>
  <!--For torque sensing in simulation-->
  <gazebo reference="j2n6s300_joint_3">
    <provideFeedback>true</provideFeedback>
  </gazebo>
  <gazebo>
    <plugin filename="libgazebo_ros_ft_sensor.so" name="ft_sensor">
      <updateRate>30.0</updateRate>
      <topicName>j2n6s300_joint_3_ft_sensor_topic</topicName>
      <jointName>j2n6s300_joint_3</jointName>
    </plugin>
  </gazebo>
  <link name="j2n6s300_link_4">
    <visual>
      <geometry>
        <mesh filename="package://kinova_description/meshes/wrist.dae"/>
      </geometry>
      <material name="carbon_fiber">
        <color rgba="0.792156862745098 0.819607843137255 0.933333333333333 1"/>
      </material>
    </visual>
    <visual>
      <geometry>
        <mesh filename="package://kinova_description/meshes/ring_small.dae"/>
      </geometry>
    </visual>
    <collision>
      <geometry>
        <mesh filename="package://kinova_description/meshes/wrist.dae"/>
      </geometry>
    </collision>
    <inertial>
      <mass value="0.426367"/>
      <origin xyz="0 -0.037 -0.0642"/>
      <inertia ixx="7.734969059999999e-05" ixy="0" ixz="0" iyy="7.734969059999999e-05" iyz="0" izz="0.0001428"/>
    </inertial>
  </link>
  <joint name="j2n6s300_joint_4" type="continuous">
    <parent link="j2n6s300_link_3"/>
    <child link="j2n6s300_link_4"/>
    <axis xyz="0 0 1"/>
    <limit effort="20" lower="-6.283185307179586" upper="6.283185307179586" velocity="0.8377580409572781"/>
    <origin rpy="-1.5707963267948966 0 3.141592653589793" xyz="0 0.2073 -0.0114"/>
    <dynamics damping="0.0" friction="0.0"/>
  </joint>
  <transmission name="j2n6s300_joint_4_trans">
    <type>transmission_interface/SimpleTransmission</type>
    <joint name="j2n6s300_joint_4">
      <hardwareInterface>hardware_interface/EffortJointInterface</hardwareInterface>
    </joint>
    <actuator name="j2n6s300_joint_4_actuator">
      <hardwareInterface>hardware_interface/EffortJointInterface</hardwareInterface>
      <mechanicalReduction>160</mechanicalReduction>
    </actuator>
  </transmission>
  <!--For torque sensing in simulation-->
  <gazebo reference="j2n6s300_joint_4">
    <provideFeedback>true</provideFeedback>
  </gazebo>
  <gazebo>
    <plugin filename="libgazebo_ros_ft_sensor.so" name="ft_sensor">
      <updateRate>30.0</updateRate>
      <topicName>j2n6s300_joint_4_ft_sensor_topic</topicName>
      <jointName>j2n6s300_joint_4</jointName>
    </plugin>
  </gazebo>
  <link name="j2n6s300_link_5">
    <visual>
      <geometry>
        <mesh filename="package://kinova_description/meshes/wrist.dae"/>
      </geometry>
      <material name="carbon_fiber">
        <color rgba="0.792156862745098 0.819607843137255 0.933333333333333 1"/>
      </material>
    </visual>
    <visual>
      <geometry>
        <mesh filename="package://kinova_description/meshes/ring_small.dae"/>
      </geometry>
    </visual>
    <collision>
      <geometry>
        <mesh filename="package://kinova_description/meshes/wrist.dae"/>
      </geometry>
    </collision>
    <inertial>
      <mass value="0.426367"/>
      <origin xyz="0 -0.037 -0.0642"/>
      <inertia ixx="7.734969059999999e-05" ixy="0" ixz="0" iyy="7.734969059999999e-05" iyz="0" izz="0.0001428"/>
    </inertial>
  </link>
  <joint name="j2n6s300_joint_5" type="continuous">
    <parent link="j2n6s300_link_4"/>
    <child link="j2n6s300_link_5"/>
    <axis xyz="0 0 1"/>
    <limit effort="20" lower="-6.283185307179586" upper="6.283185307179586" velocity="0.8377580409572781"/>
    <origin rpy="1.0471975511965976 0 3.141592653589793" xyz="0 -0.03703 -0.06414"/>
    <dynamics damping="0.0" friction="0.0"/>
  </joint>
  <transmission name="j2n6s300_joint_5_trans">
    <type>transmission_interface/SimpleTransmission</type>
    <joint name="j2n6s300_joint_5">
      <hardwareInterface>hardware_interface/EffortJointInterface</hardwareInterface>
    </joint>
    <actuator name="j2n6s300_joint_5_actuator">
      <hardwareInterface>hardware_interface/EffortJointInterface</hardwareInterface>
      <mechanicalReduction>160</mechanicalReduction>
    </actuator>
  </transmission>
  <!--For torque sensing in simulation-->
  <gazebo reference="j2n6s300_joint_5">
    <provideFeedback>true</provideFeedback>
  </gazebo>
  <gazebo>
    <plugin filename="libgazebo_ros_ft_sensor.so" name="ft_sensor">
      <updateRate>30.0</updateRate>
      <topicName>j2n6s300_joint_5_ft_sensor_topic</topicName>
      <jointName>j2n6s300_joint_5</jointName>
    </plugin>
  </gazebo>
  <link name="j2n6s300_link_6">
    <visual>
      <geometry>
        <mesh filename="package://kinova_description/meshes/hand_3finger.dae"/>
      </geometry>
      <material name="carbon_fiber">
        <color rgba="0.792156862745098 0.819607843137255 0.933333333333333 1"/>
      </material>
    </visual>
    <visual>
      <geometry>
        <mesh filename="package://kinova_description/meshes/ring_small.dae"/>
      </geometry>
    </visual>
    <collision>
      <geometry>
        <mesh filename="package://kinova_description/meshes/hand_3finger.dae"/>
      </geometry>
    </collision>
    <inertial>
      <mass value="0.99"/>
      <origin xyz="0 0 -0.06"/>
      <inertia ixx="0.00034532361869999995" ixy="0" ixz="0" iyy="0.00034532361869999995" iyz="0" izz="0.0005815999999999999"/>
    </inertial>
  </link>
  <joint name="j2n6s300_joint_6" type="continuous">
    <parent link="j2n6s300_link_5"/>
    <child link="j2n6s300_link_6"/>
    <axis xyz="0 0 1"/>
    <limit effort="20" lower="-6.283185307179586" upper="6.283185307179586" velocity="0.8377580409572781"/>
    <origin rpy="1.0471975511965976 0 3.141592653589793" xyz="0 -0.03703 -0.06414"/>
    <dynamics damping="0.0" friction="0.0"/>
  </joint>
  <transmission name="j2n6s300_joint_6_trans">
    <type>transmission_interface/SimpleTransmission</type>
    <joint name="j2n6s300_joint_6">
      <hardwareInterface>hardware_interface/EffortJointInterface</hardwareInterface>
    </joint>
    <actuator name="j2n6s300_joint_6_actuator">
      <hardwareInterface>hardware_interface/EffortJointInterface</hardwareInterface>
      <mechanicalReduction>160</mechanicalReduction>
    </actuator>
  </transmission>
  <!--For torque sensing in simulation-->
  <gazebo reference="j2n6s300_joint_6">
    <provideFeedback>true</provideFeedback>
  </gazebo>
  <gazebo>
    <plugin filename="libgazebo_ros_ft_sensor.so" name="ft_sensor">
      <updateRate>30.0</updateRate>
      <topicName>j2n6s300_joint_6_ft_sensor_topic</topicName>
      <jointName>j2n6s300_joint_6</jointName>
    </plugin>
  </gazebo>
  <link name="j2n6s300_end_effector"/>
  <joint name="j2n6s300_joint_end_effector" type="fixed">
    <parent link="j2n6s300_link_6"/>
    <child link="j2n6s300_end_effector"/>
    <axis xyz="0 0 0"/>
    <limit effort="2000" lower="0" upper="0" velocity="1"/>
    <origin rpy="3.141592653589793 0 1.5707963267948966" xyz="0 0 -0.1600"/>
  </joint>
  <link name="j2n6s300_link_finger_1">
    <visual>
      <geometry>
        <mesh filename="package://kinova_description/meshes/finger_proximal.dae"/>
      </geometry>
      <material name="carbon_fiber">
        <color rgba="0.792156862745098 0.819607843137255 0.933333333333333 1"/>
      </material>
    </visual>
    <collision>
      <geometry>
        <mesh filename="package://kinova_description/meshes/finger_proximal.dae"/>
      </geometry>
    </collision>
    <inertial>
      <mass value="0.01"/>
      <origin xyz="0.022 0 0"/>
      <inertia ixx="7.8999684e-07" ixy="0" ixz="0" iyy="7.8999684e-07" iyz="0" izz="8e-08"/>
    </inertial>
  </link>
  <joint name="j2n6s300_joint_finger_1" type="revolute">
    <parent link="j2n6s300_link_6"/>
    <child link="j2n6s300_link_finger_1"/>
    <axis xyz="0 0 1"/>
    <origin rpy="-1.570796327 .649262481663582 1.35961148639407" xyz="0.00279 0.03126 -0.11467"/>
    <limit effort="2" lower="0" upper="1.51" velocity="1"/>
  </joint>
  <transmission name="j2n6s300_joint_finger_1_trans">
    <type>transmission_interface/SimpleTransmission</type>
    <joint name="j2n6s300_joint_finger_1">
      <hardwareInterface>hardware_interface/EffortJointInterface</hardwareInterface>
    </joint>
    <actuator name="j2n6s300_joint_finger_1_actuator">
      <hardwareInterface>hardware_interface/EffortJointInterface</hardwareInterface>
      <mechanicalReduction>1</mechanicalReduction>
    </actuator>
  </transmission>
  <link name="j2n6s300_link_finger_tip_1">
    <visual>
      <geometry>
        <mesh filename="package://kinova_description/meshes/finger_distal.dae"/>
      </geometry>
      <material name="carbon_fiber">
        <color rgba="0.792156862745098 0.819607843137255 0.933333333333333 1"/>
      </material>
    </visual>
    <collision>
      <geometry>
        <mesh filename="package://kinova_description/meshes/finger_distal.dae"/>
      </geometry>
    </collision>
    <inertial>
      <mass value="0.01"/>
      <origin xyz="0.022 0 0"/>
      <inertia ixx="7.8999684e-07" ixy="0" ixz="0" iyy="7.8999684e-07" iyz="0" izz="8e-08"/>
    </inertial>
  </link>
  <joint name="j2n6s300_joint_finger_tip_1" type="revolute">
    <parent link="j2n6s300_link_finger_1"/>
    <child link="j2n6s300_link_finger_tip_1"/>
    <axis xyz="0 0 1"/>
    <origin rpy="0 0 0" xyz="0.044 -0.003 0"/>
    <limit effort="2" lower="0" upper="2" velocity="1"/>
  </joint>
  <transmission name="j2n6s300_joint_finger_tip_1_trans">
    <type>transmission_interface/SimpleTransmission</type>
    <joint name="j2n6s300_joint_finger_tip_1">
      <hardwareInterface>hardware_interface/EffortJointInterface</hardwareInterface>
    </joint>
    <actuator name="j2n6s300_joint_finger_tip_1_actuator">
      <hardwareInterface>hardware_interface/EffortJointInterface</hardwareInterface>
      <mechanicalReduction>1</mechanicalReduction>
    </actuator>
  </transmission>
  <link name="j2n6s300_link_finger_2">
    <visual>
      <geometry>
        <mesh filename="package://kinova_description/meshes/finger_proximal.dae"/>
      </geometry>
      <material name="carbon_fiber">
        <color rgba="0.792156862745098 0.819607843137255 0.933333333333333 1"/>
      </material>
    </visual>
    <collision>
      <geometry>
        <mesh filename="package://kinova_description/meshes/finger_proximal.dae"/>
      </geometry>
    </collision>
    <inertial>
      <mass value="0.01"/>
      <origin xyz="0.022 0 0"/>
      <inertia ixx="7.8999684e-07" ixy="0" ixz="0" iyy="7.8999684e-07" iyz="0" izz="8e-08"/>
    </inertial>
  </link>
  <joint name="j2n6s300_joint_finger_2" type="revolute">
    <parent link="j2n6s300_link_6"/>
    <child link="j2n6s300_link_finger_2"/>
    <axis xyz="0 0 1"/>
    <origin rpy="-1.570796327 .649262481663582 -1.38614049188413" xyz="0.02226 -0.02707 -0.11482"/>
    <limit effort="2" lower="0" upper="1.51" velocity="1"/>
  </joint>
  <transmission name="j2n6s300_joint_finger_2_trans">
    <type>transmission_interface/SimpleTransmission</type>
    <joint name="j2n6s300_joint_finger_2">
      <hardwareInterface>hardware_interface/EffortJointInterface</hardwareInterface>
    </joint>
    <actuator name="j2n6s300_joint_finger_2_actuator">
      <hardwareInterface>hardware_interface/EffortJointInterface</hardwareInterface>
      <mechanicalReduction>1</mechanicalReduction>
    </actuator>
  </transmission>
  <link name="j2n6s300_link_finger_tip_2">
    <visual>
      <geometry>
        <mesh filename="package://kinova_description/meshes/finger_distal.dae"/>
      </geometry>
      <material name="carbon_fiber">
        <color rgba="0.792156862745098 0.819607843137255 0.933333333333333 1"/>
      </material>
    </visual>
    <collision>
      <geometry>
        <mesh filename="package://kinova_description/meshes/finger_distal.dae"/>
      </geometry>
    </collision>
    <inertial>
      <mass value="0.01"/>
      <origin xyz="0.022 0 0"/>
      <inertia ixx="7.8999684e-07" ixy="0" ixz="0" iyy="7.8999684e-07" iyz="0" izz="8e-08"/>
    </inertial>
  </link>
  <joint name="j2n6s300_joint_finger_tip_2" type="revolute">
    <parent link="j2n6s300_link_finger_2"/>
    <child link="j2n6s300_link_finger_tip_2"/>
    <axis xyz="0 0 1"/>
    <origin rpy="0 0 0" xyz="0.044 -0.003 0"/>
    <limit effort="2" lower="0" upper="2" velocity="1"/>
  </joint>
  <transmission name="j2n6s300_joint_finger_tip_2_trans">
    <type>transmission_interface/SimpleTransmission</type>
    <joint name="j2n6s300_joint_finger_tip_2">
      <hardwareInterface>hardware_interface/EffortJointInterface</hardwareInterface>
    </joint>
    <actuator name="j2n6s300_joint_finger_tip_2_actuator">
      <hardwareInterface>hardware_interface/EffortJointInterface</hardwareInterface>
      <mechanicalReduction>1</mechanicalReduction>
    </actuator>
  </transmission>
  <link name="j2n6s300_link_finger_3">
    <visual>
      <geometry>
        <mesh filename="package://kinova_description/meshes/finger_proximal.dae"/>
      </geometry>
      <material name="carbon_fiber">
        <color rgba="0.792156862745098 0.819607843137255 0.933333333333333 1"/>
      </material>
    </visual>
    <collision>
      <geometry>
        <mesh filename="package://kinova_description/meshes/finger_proximal.dae"/>
      </geometry>
    </collision>
    <inertial>
      <mass value="0.01"/>
      <origin xyz="0.022 0 0"/>
      <inertia ixx="7.8999684e-07" ixy="0" ixz="0" iyy="7.8999684e-07" iyz="0" izz="8e-08"/>
    </inertial>
  </link>
  <joint name="j2n6s300_joint_finger_3" type="revolute">
    <parent link="j2n6s300_link_6"/>
    <child link="j2n6s300_link_finger_3"/>
    <axis xyz="0 0 1"/>
    <origin rpy="-1.570796327 .649262481663582 -1.75545216211587" xyz="-0.02226 -0.02707 -0.11482"/>
    <limit effort="2" lower="0" upper="1.51" velocity="1"/>
  </joint>
  <transmission name="j2n6s300_joint_finger_3_trans">
    <type>transmission_interface/SimpleTransmission</type>
    <joint name="j2n6s300_joint_finger_3">
      <hardwareInterface>hardware_interface/EffortJointInterface</hardwareInterface>
    </joint>
    <actuator name="j2n6s300_joint_finger_3_actuator">
      <hardwareInterface>hardware_interface/EffortJointInterface</hardwareInterface>
      <mechanicalReduction>1</mechanicalReduction>
    </actuator>
  </transmission>
  <link name="j2n6s300_link_finger_tip_3">
    <visual>
      <geometry>
        <mesh filename="package://kinova_description/meshes/finger_distal.dae"/>
      </geometry>
      <material name="carbon_fiber">
        <color rgba="0.792156862745098 0.819607843137255 0.933333333333333 1"/>
      </material>
    </visual>
    <collision>
      <geometry>
        <mesh filename="package://kinova_description/meshes/finger_distal.dae"/>
      </geometry>
    </collision>
    <inertial>
      <mass value="0.01"/>
      <origin xyz="0.022 0 0"/>
      <inertia ixx="7.8999684e-07" ixy="0" ixz="0" iyy="7.8999684e-07" iyz="0" izz="8e-08"/>
    </inertial>
  </link>
  <joint name="j2n6s300_joint_finger_tip_3" type="revolute">
    <parent link="j2n6s300_link_finger_3"/>
    <child link="j2n6s300_link_finger_tip_3"/>
    <axis xyz="0 0 1"/>
    <origin rpy="0 0 0" xyz="0.044 -0.003 0"/>
    <limit effort="2" lower="0" upper="2" velocity="1"/>
  </joint>
  <transmission name="j2n6s300_joint_finger_tip_3_trans">
    <type>transmission_interface/SimpleTransmission</type>
    <joint name="j2n6s300_joint_finger_tip_3">
      <hardwareInterface>hardware_interface/EffortJointInterface</hardwareInterface>
    </joint>
    <actuator name="j2n6s300_joint_finger_tip_3_actuator">
      <hardwareInterface>hardware_interface/EffortJointInterface</hardwareInterface>
      <mechanicalReduction>1</mechanicalReduction>
    </actuator>
  </transmission>

  <!-- Allegro urdf parameters added-->
   <link name="palm_link">
    <visual>
      <geometry>
        <mesh filename="package://allegro_hand_description/meshes/base_link.STL"/>
      </geometry>
      <origin rpy="0 0 0" xyz="0 0 0 "/>
      <material name="black">
        <color rgba="0.2 0.2 0.2 1"/>
      </material>
    </visual>
    <collision>
      <origin rpy="0 0 0" xyz="-0.009300 0 -0.0475"/>
      <geometry>
        <box size="0.0408 0.1130 0.095"/>
      </geometry>
    </collision>
    <inertial>
      <origin rpy="0 0 0" xyz="0 0 0.0475"/>
      <mass value="0.4154"/>
      <inertia ixx="1e-4" ixy="0.0" ixz="0.0" iyy="1e-4" iyz="0.0" izz="1e-4"/>
    </inertial>
  </link>
  <!-- ============================================================================= -->
  <!-- FINGERS -->
  <!-- RIGHT HAND due to which finger is number 0 -->
  <!-- for LEFT HAND switch the sign of the **offset_origin_y** and **finger_angle_r** parameters-->
  <!-- [LINK 0, 4, 8] -->
  <link name="link_0.0">
    <visual>
      <geometry>
        <mesh filename="package://allegro_hand_description/meshes/link_0.0.STL"/>
      </geometry>
      <material name="black"/>
    </visual>
    <collision>
      <geometry>
        <box size="0.0196 0.0275 0.0164"/>
      </geometry>
      <origin rpy="0 0 0" xyz="0 0 0.0082"/>
    </collision>
    <inertial>
      <mass value="0.0119"/>
      <origin rpy="0 0 0" xyz="0 0 0"/>
      <inertia ixx="1.01666658333e-06" ixy="0.0" ixz="0.0" iyy="6.47677333333e-07" iyz="0.0" izz="1.01666658333e-06"/>
    </inertial>
  </link>
  <joint name="joint_0.0" type="revolute">
    <axis xyz="0 0 1"/>
    <limit effort="15" lower="-0.47" upper="0.47" velocity="7"/>
    <parent link="palm_link"/>
    <child link="link_0.0"/>
    <origin rpy="-0.08726646255 0 0" xyz="0 0.0435 -0.001542"/>
    <dynamics damping="3" friction="10"/>
  </joint>
  <!-- [LINK 1, 5, 9] -->
  <link name="link_1.0">
    <visual>
      <geometry>
        <mesh filename="package://allegro_hand_description/meshes/link_1.0.STL"/>
      </geometry>
      <material name="black"/>
    </visual>
    <collision>
      <geometry>
        <box size="0.0196 0.0275 0.054"/>
      </geometry>
      <origin rpy="0 0 0" xyz="0 0 0.027"/>
    </collision>
    <inertial>
      <mass value="0.065"/>
      <origin rpy="0 0 0" xyz="0 0 0"/>
      <inertia ixx="7.95654166667e-05" ixy="1.7199e-05" ixz="8.75875e-06" iyy="2.47088833333e-05" iyz="2.413125e-05" izz="7.95654166667e-05"/>
    </inertial>
  </link>
  <joint name="joint_1.0" type="revolute">
    <limit effort="15" lower="-0.196" upper="1.61" velocity="7"/>
    <axis xyz="0 1 0"/>
    <parent link="link_0.0"/>
    <child link="link_1.0"/>
    <origin xyz="0 0 0.0164"/>
    <dynamics damping="3" friction="5"/>
  </joint>
  <!-- [LINK 2, 6, 10]-->
  <link name="link_2.0">
    <visual>
      <geometry>
        <mesh filename="package://allegro_hand_description/meshes/link_2.0.STL"/>
      </geometry>
      <material name="black"/>
    </visual>
    <collision>
      <geometry>
        <box size="0.0196 0.0275 0.0384"/>
      </geometry>
      <origin rpy="0 0 0" xyz="0 0 0.0192"/>
    </collision>
    <inertial>
      <mass value="0.0355"/>
      <origin rpy="0 0 0" xyz="0 0 0"/>
      <inertia ixx="2.63979183333e-05" ixy="6.67968e-06" ixz="4.783625e-06" iyy="1.34948516667e-05" iyz="9.372e-06" izz="2.63979183333e-05"/>
    </inertial>
  </link>
  <joint name="joint_2.0" type="revolute">
    <axis xyz="0 1 0"/>
    <limit effort="15" lower="-0.174" upper="1.709" velocity="7"/>
    <parent link="link_1.0"/>
    <child link="link_2.0"/>
    <origin xyz="0 0 0.054"/>
    <dynamics damping="8" friction="10"/>
  </joint>
  <!-- [LINK 3, 7, 11] -->
  <link name="link_3.0">
    <visual>
      <geometry>
        <mesh filename="package://allegro_hand_description/meshes/link_3.0.STL"/>
      </geometry>
      <material name="black"/>
    </visual>
    <collision>
      <geometry>
        <box size="0.0196 0.0275 0.0267"/>
      </geometry>
      <origin rpy="0 0 0" xyz="0 0 0.01335"/>
    </collision>
    <inertial>
      <mass value="0.0096"/>
      <origin rpy="0 0 0" xyz="0 0 0"/>
      <inertia ixx="4.701248e-06" ixy="1.255968e-06" ixz="1.2936e-06" iyy="3.649312e-06" iyz="1.7622e-06" izz="4.701248e-06"/>
    </inertial>
  </link>
  <joint name="joint_3.0" type="revolute">
    <axis xyz="0 1 0"/>
    <limit effort="15" lower="-0.227" upper="1.618" velocity="7"/>
    <parent link="link_2.0"/>
    <child link="link_3.0"/>
    <origin xyz="0 0 0.0384"/>
    <dynamics damping="10" friction="12"/>
  </joint>
  <!-- [FINGER TIP] -->
  <link name="link_3.0_tip">
    <visual>
      <geometry>
        <mesh filename="package://allegro_hand_description/meshes/link_3.0_tip.STL"/>
      </geometry>
      <material name="white">
        <color rgba=".9 .9 .9 1"/>
      </material>
    </visual>
    <collision>
      <geometry>
        <sphere radius="0.012"/>
      </geometry>
    </collision>
    <inertial>
      <mass value="0.0168"/>
      <origin rpy="0 0 0" xyz="0 0 0"/>
      <inertia ixx="9.68e-07" ixy="0" ixz="0" iyy="9.68e-07" iyz="0" izz="9.68e-07"/>
    </inertial>
  </link>
  <joint name="joint_3.0_tip" type="fixed">
    <parent link="link_3.0"/>
    <child link="link_3.0_tip"/>
    <origin rpy="0 0 0" xyz="0 0 0.0267"/>
  </joint>
  <!-- [LINK 0, 4, 8] -->
  <link name="link_4.0">
    <visual>
      <geometry>
        <mesh filename="package://allegro_hand_description/meshes/link_0.0.STL"/>
      </geometry>
      <material name="black"/>
    </visual>
    <collision>
      <geometry>
        <box size="0.0196 0.0275 0.0164"/>
      </geometry>
      <origin rpy="0 0 0" xyz="0 0 0.0082"/>
    </collision>
    <inertial>
      <mass value="0.0119"/>
      <origin rpy="0 0 0" xyz="0 0 0"/>
      <inertia ixx="1.01666658333e-06" ixy="0.0" ixz="0.0" iyy="6.47677333333e-07" iyz="0.0" izz="1.01666658333e-06"/>
    </inertial>
  </link>
  <joint name="joint_4.0" type="revolute">
    <axis xyz="0 0 1"/>
    <limit effort="15" lower="-0.47" upper="0.47" velocity="7"/>
    <parent link="palm_link"/>
    <child link="link_4.0"/>
    <origin rpy="0.0 0 0" xyz="0 0 0.0007"/>
    <dynamics damping="3" friction="10"/>
  </joint>
  <!-- [LINK 1, 5, 9] -->
  <link name="link_5.0">
    <visual>
      <geometry>
        <mesh filename="package://allegro_hand_description/meshes/link_1.0.STL"/>
      </geometry>
      <material name="black"/>
    </visual>
    <collision>
      <geometry>
        <box size="0.0196 0.0275 0.054"/>
      </geometry>
      <origin rpy="0 0 0" xyz="0 0 0.027"/>
    </collision>
    <inertial>
      <mass value="0.065"/>
      <origin rpy="0 0 0" xyz="0 0 0"/>
      <inertia ixx="7.95654166667e-05" ixy="1.7199e-05" ixz="8.75875e-06" iyy="2.47088833333e-05" iyz="2.413125e-05" izz="7.95654166667e-05"/>
    </inertial>
  </link>
  <joint name="joint_5.0" type="revolute">
    <limit effort="15" lower="-0.196" upper="1.61" velocity="7"/>
    <axis xyz="0 1 0"/>
    <parent link="link_4.0"/>
    <child link="link_5.0"/>
    <origin xyz="0 0 0.0164"/>
    <dynamics damping="3" friction="5"/>
  </joint>
  <!-- [LINK 2, 6, 10]-->
  <link name="link_6.0">
    <visual>
      <geometry>
        <mesh filename="package://allegro_hand_description/meshes/link_2.0.STL"/>
      </geometry>
      <material name="black"/>
    </visual>
    <collision>
      <geometry>
        <box size="0.0196 0.0275 0.0384"/>
      </geometry>
      <origin rpy="0 0 0" xyz="0 0 0.0192"/>
    </collision>
    <inertial>
      <mass value="0.0355"/>
      <origin rpy="0 0 0" xyz="0 0 0"/>
      <inertia ixx="2.63979183333e-05" ixy="6.67968e-06" ixz="4.783625e-06" iyy="1.34948516667e-05" iyz="9.372e-06" izz="2.63979183333e-05"/>
    </inertial>
  </link>
  <joint name="joint_6.0" type="revolute">
    <axis xyz="0 1 0"/>
    <limit effort="15" lower="-0.174" upper="1.709" velocity="7"/>
    <parent link="link_5.0"/>
    <child link="link_6.0"/>
    <origin xyz="0 0 0.054"/>
    <dynamics damping="8" friction="10"/>
  </joint>
  <!-- [LINK 3, 7, 11] -->
  <link name="link_7.0">
    <visual>
      <geometry>
        <mesh filename="package://allegro_hand_description/meshes/link_3.0.STL"/>
      </geometry>
      <material name="black"/>
    </visual>
    <collision>
      <geometry>
        <box size="0.0196 0.0275 0.0267"/>
      </geometry>
      <origin rpy="0 0 0" xyz="0 0 0.01335"/>
    </collision>
    <inertial>
      <mass value="0.0096"/>
      <origin rpy="0 0 0" xyz="0 0 0"/>
      <inertia ixx="4.701248e-06" ixy="1.255968e-06" ixz="1.2936e-06" iyy="3.649312e-06" iyz="1.7622e-06" izz="4.701248e-06"/>
    </inertial>
  </link>
  <joint name="joint_7.0" type="revolute">
    <axis xyz="0 1 0"/>
    <limit effort="15" lower="-0.227" upper="1.618" velocity="7"/>
    <parent link="link_6.0"/>
    <child link="link_7.0"/>
    <origin xyz="0 0 0.0384"/>
    <dynamics damping="10" friction="12"/>
  </joint>
  <!-- [FINGER TIP] -->
  <link name="link_7.0_tip">
    <visual>
      <geometry>
        <mesh filename="package://allegro_hand_description/meshes/link_3.0_tip.STL"/>
      </geometry>
      <material name="white">
        <color rgba=".9 .9 .9 1"/>
      </material>
    </visual>
    <collision>
      <geometry>
        <sphere radius="0.012"/>
      </geometry>
    </collision>
    <inertial>
      <mass value="0.0168"/>
      <origin rpy="0 0 0" xyz="0 0 0"/>
      <inertia ixx="9.68e-07" ixy="0" ixz="0" iyy="9.68e-07" iyz="0" izz="9.68e-07"/>
    </inertial>
  </link>
  <joint name="joint_7.0_tip" type="fixed">
    <parent link="link_7.0"/>
    <child link="link_7.0_tip"/>
    <origin rpy="0 0 0" xyz="0 0 0.0267"/>
  </joint>
  <!-- [LINK 0, 4, 8] -->
  <link name="link_8.0">
    <visual>
      <geometry>
        <mesh filename="package://allegro_hand_description/meshes/link_0.0.STL"/>
      </geometry>
      <material name="black"/>
    </visual>
    <collision>
      <geometry>
        <box size="0.0196 0.0275 0.0164"/>
      </geometry>
      <origin rpy="0 0 0" xyz="0 0 0.0082"/>
    </collision>
    <inertial>
      <mass value="0.0119"/>
      <origin rpy="0 0 0" xyz="0 0 0"/>
      <inertia ixx="1.01666658333e-06" ixy="0.0" ixz="0.0" iyy="6.47677333333e-07" iyz="0.0" izz="1.01666658333e-06"/>
    </inertial>
  </link>
  <joint name="joint_8.0" type="revolute">
    <axis xyz="0 0 1"/>
    <limit effort="15" lower="-0.47" upper="0.47" velocity="7"/>
    <parent link="palm_link"/>
    <child link="link_8.0"/>
    <origin rpy="0.08726646255 0 0" xyz="0 -0.0435 -0.001542"/>
    <dynamics damping="3" friction="10"/>
  </joint>
  <!-- [LINK 1, 5, 9] -->
  <link name="link_9.0">
    <visual>
      <geometry>
        <mesh filename="package://allegro_hand_description/meshes/link_1.0.STL"/>
      </geometry>
      <material name="black"/>
    </visual>
    <collision>
      <geometry>
        <box size="0.0196 0.0275 0.054"/>
      </geometry>
      <origin rpy="0 0 0" xyz="0 0 0.027"/>
    </collision>
    <inertial>
      <mass value="0.065"/>
      <origin rpy="0 0 0" xyz="0 0 0"/>
      <inertia ixx="7.95654166667e-05" ixy="1.7199e-05" ixz="8.75875e-06" iyy="2.47088833333e-05" iyz="2.413125e-05" izz="7.95654166667e-05"/>
    </inertial>
  </link>
  <joint name="joint_9.0" type="revolute">
    <limit effort="15" lower="-0.196" upper="1.61" velocity="7"/>
    <axis xyz="0 1 0"/>
    <parent link="link_8.0"/>
    <child link="link_9.0"/>
    <origin xyz="0 0 0.0164"/>
    <dynamics damping="3" friction="5"/>
  </joint>
  <!-- [LINK 2, 6, 10]-->
  <link name="link_10.0">
    <visual>
      <geometry>
        <mesh filename="package://allegro_hand_description/meshes/link_2.0.STL"/>
      </geometry>
      <material name="black"/>
    </visual>
    <collision>
      <geometry>
        <box size="0.0196 0.0275 0.0384"/>
      </geometry>
      <origin rpy="0 0 0" xyz="0 0 0.0192"/>
    </collision>
    <inertial>
      <mass value="0.0355"/>
      <origin rpy="0 0 0" xyz="0 0 0"/>
      <inertia ixx="2.63979183333e-05" ixy="6.67968e-06" ixz="4.783625e-06" iyy="1.34948516667e-05" iyz="9.372e-06" izz="2.63979183333e-05"/>
    </inertial>
  </link>
  <joint name="joint_10.0" type="revolute">
    <axis xyz="0 1 0"/>
    <limit effort="15" lower="-0.174" upper="1.709" velocity="7"/>
    <parent link="link_9.0"/>
    <child link="link_10.0"/>
    <origin xyz="0 0 0.054"/>
    <dynamics damping="8" friction="10"/>
  </joint>
  <!-- [LINK 3, 7, 11] -->
  <link name="link_11.0">
    <visual>
      <geometry>
        <mesh filename="package://allegro_hand_description/meshes/link_3.0.STL"/>
      </geometry>
      <material name="black"/>
    </visual>
    <collision>
      <geometry>
        <box size="0.0196 0.0275 0.0267"/>
      </geometry>
      <origin rpy="0 0 0" xyz="0 0 0.01335"/>
    </collision>
    <inertial>
      <mass value="0.0096"/>
      <origin rpy="0 0 0" xyz="0 0 0"/>
      <inertia ixx="4.701248e-06" ixy="1.255968e-06" ixz="1.2936e-06" iyy="3.649312e-06" iyz="1.7622e-06" izz="4.701248e-06"/>
    </inertial>
  </link>
  <joint name="joint_11.0" type="revolute">
    <axis xyz="0 1 0"/>
    <limit effort="15" lower="-0.227" upper="1.618" velocity="7"/>
    <parent link="link_10.0"/>
    <child link="link_11.0"/>
    <origin xyz="0 0 0.0384"/>
    <dynamics damping="10" friction="12"/>
  </joint>
  <!-- [FINGER TIP] -->
  <link name="link_11.0_tip">
    <visual>
      <geometry>
        <mesh filename="package://allegro_hand_description/meshes/link_3.0_tip.STL"/>
      </geometry>
      <material name="white">
        <color rgba=".9 .9 .9 1"/>
      </material>
    </visual>
    <collision>
      <geometry>
        <sphere radius="0.012"/>
      </geometry>
    </collision>
    <inertial>
      <mass value="0.0168"/>
      <origin rpy="0 0 0" xyz="0 0 0"/>
      <inertia ixx="9.68e-07" ixy="0" ixz="0" iyy="9.68e-07" iyz="0" izz="9.68e-07"/>
    </inertial>
  </link>
  <joint name="joint_11.0_tip" type="fixed">
    <parent link="link_11.0"/>
    <child link="link_11.0_tip"/>
    <origin rpy="0 0 0" xyz="0 0 0.0267"/>
  </joint>
  <!-- THUMB -->
  <!-- [LINK 12] -->
  <link name="link_12.0">
    <visual>
      <geometry>
        <mesh filename="package://allegro_hand_description/meshes/link_12.0_right.STL"/>
      </geometry>
      <material name="black">
        <color rgba=".2 .2 .2 1"/>
      </material>
      <origin rpy="3.1415926518 0 0" xyz="0 0 0"/>
    </visual>
    <collision>
      <geometry>
        <box size="0.0358 0.034 0.0455"/>
      </geometry>
      <origin rpy="0 0 0" xyz="-0.0179 0.009 0.0145"/>
    </collision>
    <inertial>
      <mass value="0.0176"/>
      <origin rpy="0 0 0" xyz="0 0 0"/>
      <inertia ixx="1.89273333333e-5" ixy="7.16716e-06" ixz="5.35568e-06" iyy="1.43008213333e-05" iyz="6.8068e-06" izz="1.89273333333e-05"/>
    </inertial>
  </link>
  <joint name="joint_12.0" type="revolute">
    <axis xyz="-1 0 0"/>
    <limit effort="15" lower="0.263" upper="1.396" velocity="7"/>
    <parent link="palm_link"/>
    <child link="link_12.0"/>
    <origin rpy="0 -1.65806278845 -1.5707963259" xyz="-0.0182 0.019333 -0.045987"/>
    <dynamics damping="3" friction="10"/>
  </joint>
  <!-- [LINK 13] -->
  <link name="link_13.0">
    <visual>
      <geometry>
        <mesh filename="package://allegro_hand_description/meshes/link_13.0.STL"/>
      </geometry>
      <material name="black">
        <color rgba=".2 .2 .2 1"/>
      </material>
    </visual>
    <collision>
      <geometry>
        <box size="0.0196 0.0275 0.0177"/>
      </geometry>
      <origin rpy="0 0 0" xyz="0 0 0.00885"/>
    </collision>
    <inertial>
      <mass value="0.0119"/>
      <origin rpy="0 0 0" xyz="0 0 0"/>
      <inertia ixx="4.24250866667e-06" ixy="1.032087e-06" ixz="1.603525e-06" iyy="4.52362633333e-06" iyz="1.44808125e-06" izz="4.24250866667e-06"/>
    </inertial>
  </link>
  <joint name="joint_13.0" type="revolute">
    <axis xyz="0 0 1"/>
    <limit effort="15" lower="-0.105" upper="1.163" velocity="7"/>
    <parent link="link_12.0"/>
    <child link="link_13.0"/>
    <origin xyz="-0.027 0.005 0.0399"/>
    <dynamics damping="3" friction="5"/>
  </joint>
  <!-- [LINK 14] -->
  <link name="link_14.0">
    <visual>
      <geometry>
        <mesh filename="package://allegro_hand_description/meshes/link_14.0.STL"/>
      </geometry>
      <material name="black">
                </material>
    </visual>
    <collision>
      <geometry>
        <box size="0.0196 0.0275 0.0514"/>
      </geometry>
      <origin rpy="0 0 0" xyz="0 0 0.0257"/>
    </collision>
    <inertial>
      <mass value="0.038"/>
      <origin rpy="0 0 0" xyz="0 0 0"/>
      <inertia ixx="4.30439933333e-05" ixy="9.57068e-06" ixz="5.1205e-06" iyy="1.44451933333e-05" iyz="1.342825e-05" izz="4.30439933333e-05"/>
    </inertial>
  </link>
  <joint name="joint_14.0" type="revolute">
    <axis xyz="0 1 0"/>
    <limit effort="15" lower="-0.189" upper="1.644" velocity="7"/>
    <parent link="link_13.0"/>
    <child link="link_14.0"/>
    <origin xyz="0 0 0.0177"/>
    <dynamics damping="3" friction="10"/>
  </joint>
  <!-- [LINK 15] -->
  <link name="link_15.0">
    <visual>
      <geometry>
        <mesh filename="package://allegro_hand_description/meshes/link_15.0.STL"/>
      </geometry>
      <material name="black">
                </material>
    </visual>
    <collision>
      <geometry>
        <box size="0.0196 0.0275 0.0423"/>
      </geometry>
      <origin rpy="0 0 0" xyz="0 0 0.02115"/>
    </collision>
    <inertial>
      <mass value="0.0388"/>
      <origin rpy="0 0 0" xyz="0 0 0"/>
      <inertia ixx="3.29223173333e-05" ixy="8.042076e-06" ixz="5.2283e-06" iyy="1.47493026667e-5" iyz="1.1283525e-5" izz="3.29223173333e-05"/>
    </inertial>
  </link>
  <joint name="joint_15.0" type="revolute">
    <axis xyz="0 1 0"/>
    <limit effort="15" lower="-0.162" upper="1.719" velocity="7"/>
    <parent link="link_14.0"/>
    <child link="link_15.0"/>
    <origin xyz="0 0 0.0514"/>
    <dynamics damping="3" friction="12"/>
  </joint>
  <!-- [FINGER TIP] -->
  <link name="link_15.0_tip">
    <visual>
      <geometry>
        <mesh filename="package://allegro_hand_description/meshes/link_15.0_tip.STL"/>
      </geometry>
      <material name="white">
        <color rgba=".9 .9 .9 1"/>
      </material>
    </visual>
    <collision>
      <geometry>
        <sphere radius="0.012"/>
      </geometry>
      <origin rpy="0 0 0" xyz="0 0 0"/>
    </collision>
    <inertial>
      <mass value="0.0168"/>
      <origin rpy="0 0 0" xyz="0 0 0"/>
      <inertia ixx="9.68e-07" ixy="0" ixz="0" iyy="9.68e-07" iyz="0" izz="9.68e-07"/>
    </inertial>
  </link>
  <joint name="joint_15.0_tip" type="fixed">
    <parent link="link_15.0"/>
    <child link="link_15.0_tip"/>
    <origin rpy="0 0 0" xyz="0 0 0.0423"/>
  </joint>
  <joint name="iiwa7_allegro" type="fixed">
    <parent link="j2n6s300_link_finger_tip_3"/>
    <child link="allegro_mount"/>
    <origin rpy="0 0 0" xyz="0 0 0"/>
  </joint>
</robot>
